<?xml version="1.0" encoding="utf-8"?><testsuites name="pytest tests"><testsuite name="pytest" errors="0" failures="1" skipped="0" tests="11" time="182.143" timestamp="2025-09-12T14:37:35.247905+00:00" hostname="dut7358"><testcase classname="test.distributed.test_functional_api.TestMetaCollectives" name="test_all_reduce" time="0.002" /><testcase classname="test.distributed.test_functional_api.TestMakeFx" name="test_all_reduce_tracing" time="0.017" /><testcase classname="test.distributed.test_functional_api.TestCollectivesWithDistributedBackendXPU" name="test_all_gather_into_tensor_coalesced_xpu" time="17.633" /><testcase classname="test.distributed.test_functional_api.TestCollectivesWithDistributedBackendXPU" name="test_all_to_all_single_1d_input_xpu" time="17.733" /><testcase classname="test.distributed.test_functional_api.TestCollectivesWithDistributedBackendXPU" name="test_all_to_all_single_split_sizes_none_xpu" time="17.732" /><testcase classname="test.distributed.test_functional_api.TestCollectivesWithDistributedBackendXPU" name="test_all_to_all_single_xpu" time="17.731" /><testcase classname="test.distributed.test_functional_api.TestCollectivesWithDistributedBackendXPU" name="test_tracing_with_dce_code_xpu" time="16.731" /><testcase classname="test.distributed.test_functional_api.TestCollectivesWithDistributedBackendXPU" name="test_tracing_with_fakepg_xpu" time="12.827"><failure message="RuntimeError: Process 0 exited with error code 10 and exception:&#10;Traceback (most recent call last):&#10;  File &quot;/tmp/xpu-tool/Python/3.10.18/x64/lib/python3.10/site-packages/torch/testing/_internal/common_distributed.py&quot;, line 864, in run_test&#10;    getattr(self, test_name)()&#10;  File &quot;/tmp/xpu-tool/Python/3.10.18/x64/lib/python3.10/site-packages/torch/testing/_internal/common_distributed.py&quot;, line 718, in wrapper&#10;    fn()&#10;  File &quot;/tmp/xpu-tool/Python/3.10.18/x64/lib/python3.10/site-packages/torch/testing/_internal/common_utils.py&quot;, line 3225, in wrapper&#10;    method(*args, **kwargs)&#10;  File &quot;/tmp/xpu-tool/Python/3.10.18/x64/lib/python3.10/site-packages/torch/testing/_internal/common_device_type.py&quot;, line 446, in instantiated_test&#10;    raise rte&#10;  File &quot;/tmp/xpu-tool/Python/3.10.18/x64/lib/python3.10/site-packages/torch/testing/_internal/common_device_type.py&quot;, line 426, in instantiated_test&#10;    result = test(self, **param_kwargs)&#10;  File &quot;/home/jenkins/actions-runner/_work/torch-xpu-ops/torch-xpu-ops/pytorch/test/distributed/test_functional_api.py&quot;, line 599, in test_tracing_with_fakepg&#10;    allreduce(torch.randn(8, device=device), pg=dist.group.WORLD)&#10;  File &quot;/home/jenkins/actions-runner/_work/torch-xpu-ops/torch-xpu-ops/pytorch/test/distributed/test_functional_api.py&quot;, line 591, in allreduce&#10;    return ft_c.all_reduce(t, &quot;sum&quot;, pg)&#10;  File &quot;/tmp/xpu-tool/Python/3.10.18/x64/lib/python3.10/site-packages/torch/distributed/_functional_collectives.py&quot;, line 170, in all_reduce&#10;    tensor = torch.ops._c10d_functional.all_reduce(self, reduceOp.lower(), group_name)&#10;  File &quot;/tmp/xpu-tool/Python/3.10.18/x64/lib/python3.10/site-packages/torch/_ops.py&quot;, line 1255, in __call__&#10;    return self._op(*args, **kwargs)&#10;RuntimeError: No backend type associated with device type xpu&#10;&#10;To execute this test, run the following from the base repo dir:&#10;    PYTORCH_TEST_WITH_SLOW=1 python test/distributed/test_functional_api.py TestCollectivesWithDistributedBackendXPU.test_tracing_with_fakepg_xpu&#10;&#10;This message can be suppressed by setting PYTORCH_PRINT_REPRO_ON_FAILURE=0">Traceback (most recent call last):
  File "/tmp/xpu-tool/Python/3.10.18/x64/lib/python3.10/unittest/case.py", line 59, in testPartExecutor
    yield
  File "/tmp/xpu-tool/Python/3.10.18/x64/lib/python3.10/unittest/case.py", line 591, in run
    self._callTestMethod(testMethod)
  File "/tmp/xpu-tool/Python/3.10.18/x64/lib/python3.10/unittest/case.py", line 549, in _callTestMethod
    method()
  File "/tmp/xpu-tool/Python/3.10.18/x64/lib/python3.10/site-packages/torch/testing/_internal/common_distributed.py", line 716, in wrapper
    self._join_processes(fn)
  File "/tmp/xpu-tool/Python/3.10.18/x64/lib/python3.10/site-packages/torch/testing/_internal/common_distributed.py", line 980, in _join_processes
    self._check_return_codes(fn, elapsed_time)
  File "/tmp/xpu-tool/Python/3.10.18/x64/lib/python3.10/site-packages/torch/testing/_internal/common_distributed.py", line 1020, in _check_return_codes
    raise RuntimeError(error)
RuntimeError: Process 0 exited with error code 10 and exception:
Traceback (most recent call last):
  File "/tmp/xpu-tool/Python/3.10.18/x64/lib/python3.10/site-packages/torch/testing/_internal/common_distributed.py", line 864, in run_test
    getattr(self, test_name)()
  File "/tmp/xpu-tool/Python/3.10.18/x64/lib/python3.10/site-packages/torch/testing/_internal/common_distributed.py", line 718, in wrapper
    fn()
  File "/tmp/xpu-tool/Python/3.10.18/x64/lib/python3.10/site-packages/torch/testing/_internal/common_utils.py", line 3225, in wrapper
    method(*args, **kwargs)
  File "/tmp/xpu-tool/Python/3.10.18/x64/lib/python3.10/site-packages/torch/testing/_internal/common_device_type.py", line 446, in instantiated_test
    raise rte
  File "/tmp/xpu-tool/Python/3.10.18/x64/lib/python3.10/site-packages/torch/testing/_internal/common_device_type.py", line 426, in instantiated_test
    result = test(self, **param_kwargs)
  File "/home/jenkins/actions-runner/_work/torch-xpu-ops/torch-xpu-ops/pytorch/test/distributed/test_functional_api.py", line 599, in test_tracing_with_fakepg
    allreduce(torch.randn(8, device=device), pg=dist.group.WORLD)
  File "/home/jenkins/actions-runner/_work/torch-xpu-ops/torch-xpu-ops/pytorch/test/distributed/test_functional_api.py", line 591, in allreduce
    return ft_c.all_reduce(t, "sum", pg)
  File "/tmp/xpu-tool/Python/3.10.18/x64/lib/python3.10/site-packages/torch/distributed/_functional_collectives.py", line 170, in all_reduce
    tensor = torch.ops._c10d_functional.all_reduce(self, reduceOp.lower(), group_name)
  File "/tmp/xpu-tool/Python/3.10.18/x64/lib/python3.10/site-packages/torch/_ops.py", line 1255, in __call__
    return self._op(*args, **kwargs)
RuntimeError: No backend type associated with device type xpu

To execute this test, run the following from the base repo dir:
    PYTORCH_TEST_WITH_SLOW=1 python test/distributed/test_functional_api.py TestCollectivesWithDistributedBackendXPU.test_tracing_with_fakepg_xpu

This message can be suppressed by setting PYTORCH_PRINT_REPRO_ON_FAILURE=0</failure></testcase><testcase classname="test.distributed.test_functional_api.TestCollectivesWithDistributedBackendXPU" name="test_tracing_xpu" time="34.662" /><testcase classname="test.distributed.test_functional_api.TestDistributedBackendCollectivesWithWorldSize4XPU" name="test_permute_tensor_with_sub_group_xpu" time="18.133" /><testcase classname="test.distributed.test_functional_api.TestFunctionalAutogradWithDistributedBackendXPU" name="test_all_to_all_single_xpu" time="17.733" /></testsuite></testsuites>