<?xml version="1.0" encoding="utf-8"?><testsuites><testsuite name="pytest" errors="0" failures="1" skipped="0" tests="1" time="302.921" timestamp="2025-08-22T15:12:43.100643" hostname="dut7358"><testcase classname="test.distributed.checkpoint.test_dtensor_resharding.TestDTensorReshardMeshChange" name="test_dtensor_checkpoint_resharding_with_empty_shard" time="300.262"><failure message="RuntimeError: Process 0 terminated or timed out after 300.0380766391754 seconds">Traceback (most recent call last):
  File "/home/jenkins/.conda/envs/xpu_op_/lib/python3.10/site-packages/torch/testing/_internal/common_distributed.py", line 716, in wrapper
    self._join_processes(fn)
  File "/home/jenkins/.conda/envs/xpu_op_/lib/python3.10/site-packages/torch/testing/_internal/common_distributed.py", line 980, in _join_processes
    self._check_return_codes(fn, elapsed_time)
  File "/home/jenkins/.conda/envs/xpu_op_/lib/python3.10/site-packages/torch/testing/_internal/common_distributed.py", line 1025, in _check_return_codes
    raise RuntimeError(
RuntimeError: Process 0 terminated or timed out after 300.0380766391754 seconds</failure></testcase></testsuite></testsuites>