<?xml version="1.0" encoding="utf-8"?><testsuites><testsuite name="pytest" errors="0" failures="1" skipped="0" tests="1" time="8.082" timestamp="2025-08-31T00:35:35.065778" hostname="dut7358"><testcase classname="test.distributed.tensor.parallel.test_tp_random_state.TensorParallelRandomStateTests" name="test_model_init" time="5.736"><failure message="RuntimeError: Process 1 exited with error code 10 and exception:&#10;Traceback (most recent call last):&#10;  File &quot;/tmp/xpu-tool/Python/3.10.18/x64/lib/python3.10/site-packages/torch/testing/_internal/common_distributed.py&quot;, line 864, in run_test&#10;    getattr(self, test_name)()&#10;  File &quot;/tmp/xpu-tool/Python/3.10.18/x64/lib/python3.10/site-packages/torch/testing/_internal/common_distributed.py&quot;, line 718, in wrapper&#10;    fn()&#10;  File &quot;/tmp/xpu-tool/Python/3.10.18/x64/lib/python3.10/site-packages/torch/testing/_internal/common_utils.py&quot;, line 3226, in wrapper&#10;    method(*args, **kwargs)&#10;  File &quot;/tmp/xpu-tool/Python/3.10.18/x64/lib/python3.10/site-packages/torch/testing/_internal/distributed/_tensor/common_dtensor.py&quot;, line 491, in wrapper&#10;    raise e&#10;  File &quot;/tmp/xpu-tool/Python/3.10.18/x64/lib/python3.10/site-packages/torch/testing/_internal/distributed/_tensor/common_dtensor.py&quot;, line 488, in wrapper&#10;    func(self, *args, **kwargs)  # type: ignore[misc]&#10;  File &quot;/tmp/xpu-tool/Python/3.10.18/x64/lib/python3.10/site-packages/torch/testing/_internal/common_distributed.py&quot;, line 221, in wrapper&#10;    return func(*args, **kwargs)&#10;  File &quot;/home/jenkins/actions-runner/_work/torch-xpu-ops/torch-xpu-ops/pytorch/test/distributed/tensor/parallel/test_tp_random_state.py&quot;, line 126, in test_model_init&#10;    self.check_gathered_tensors(&#10;  File &quot;/home/jenkins/actions-runner/_work/torch-xpu-ops/torch-xpu-ops/pytorch/test/distributed/tensor/parallel/test_tp_random_state.py&quot;, line 33, in check_gathered_tensors&#10;    assertFunc(&#10;  File &quot;/home/jenkins/actions-runner/_work/torch-xpu-ops/torch-xpu-ops/pytorch/test/distributed/tensor/parallel/test_tp_random_state.py&quot;, line 124, in dp_weights_assert&#10;    self.assertEqual(tensor1, tensor2)&#10;  File &quot;/tmp/xpu-tool/Python/3.10.18/x64/lib/python3.10/site-packages/torch/testing/_internal/common_utils.py&quot;, line 4181, in assertEqual&#10;    raise error_metas.pop()[0].to_error(  # type: ignore[index]&#10;AssertionError: Tensor-likes are not close!&#10;&#10;Mismatched elements: 80 / 80 (100.0%)&#10;Greatest absolute difference: 0.5629510879516602 at index (4, 4) (up to 1e-05 allowed)&#10;Greatest relative difference: 33.426822662353516 at index (5, 5) (up to 1.3e-06 allowed)&#10;&#10;To execute this test, run the following from the base repo dir:&#10;    PYTORCH_TEST_WITH_SLOW=1 python test/distributed/tensor/parallel/test_tp_random_state.py TensorParallelRandomStateTests.test_model_init&#10;&#10;This message can be suppressed by setting PYTORCH_PRINT_REPRO_ON_FAILURE=0">Traceback (most recent call last):
  File "/tmp/xpu-tool/Python/3.10.18/x64/lib/python3.10/site-packages/torch/testing/_internal/common_distributed.py", line 716, in wrapper
    self._join_processes(fn)
  File "/tmp/xpu-tool/Python/3.10.18/x64/lib/python3.10/site-packages/torch/testing/_internal/common_distributed.py", line 980, in _join_processes
    self._check_return_codes(fn, elapsed_time)
  File "/tmp/xpu-tool/Python/3.10.18/x64/lib/python3.10/site-packages/torch/testing/_internal/common_distributed.py", line 1020, in _check_return_codes
    raise RuntimeError(error)
RuntimeError: Process 1 exited with error code 10 and exception:
Traceback (most recent call last):
  File "/tmp/xpu-tool/Python/3.10.18/x64/lib/python3.10/site-packages/torch/testing/_internal/common_distributed.py", line 864, in run_test
    getattr(self, test_name)()
  File "/tmp/xpu-tool/Python/3.10.18/x64/lib/python3.10/site-packages/torch/testing/_internal/common_distributed.py", line 718, in wrapper
    fn()
  File "/tmp/xpu-tool/Python/3.10.18/x64/lib/python3.10/site-packages/torch/testing/_internal/common_utils.py", line 3226, in wrapper
    method(*args, **kwargs)
  File "/tmp/xpu-tool/Python/3.10.18/x64/lib/python3.10/site-packages/torch/testing/_internal/distributed/_tensor/common_dtensor.py", line 491, in wrapper
    raise e
  File "/tmp/xpu-tool/Python/3.10.18/x64/lib/python3.10/site-packages/torch/testing/_internal/distributed/_tensor/common_dtensor.py", line 488, in wrapper
    func(self, *args, **kwargs)  # type: ignore[misc]
  File "/tmp/xpu-tool/Python/3.10.18/x64/lib/python3.10/site-packages/torch/testing/_internal/common_distributed.py", line 221, in wrapper
    return func(*args, **kwargs)
  File "/home/jenkins/actions-runner/_work/torch-xpu-ops/torch-xpu-ops/pytorch/test/distributed/tensor/parallel/test_tp_random_state.py", line 126, in test_model_init
    self.check_gathered_tensors(
  File "/home/jenkins/actions-runner/_work/torch-xpu-ops/torch-xpu-ops/pytorch/test/distributed/tensor/parallel/test_tp_random_state.py", line 33, in check_gathered_tensors
    assertFunc(
  File "/home/jenkins/actions-runner/_work/torch-xpu-ops/torch-xpu-ops/pytorch/test/distributed/tensor/parallel/test_tp_random_state.py", line 124, in dp_weights_assert
    self.assertEqual(tensor1, tensor2)
  File "/tmp/xpu-tool/Python/3.10.18/x64/lib/python3.10/site-packages/torch/testing/_internal/common_utils.py", line 4181, in assertEqual
    raise error_metas.pop()[0].to_error(  # type: ignore[index]
AssertionError: Tensor-likes are not close!

Mismatched elements: 80 / 80 (100.0%)
Greatest absolute difference: 0.5629510879516602 at index (4, 4) (up to 1e-05 allowed)
Greatest relative difference: 33.426822662353516 at index (5, 5) (up to 1.3e-06 allowed)

To execute this test, run the following from the base repo dir:
    PYTORCH_TEST_WITH_SLOW=1 python test/distributed/tensor/parallel/test_tp_random_state.py TensorParallelRandomStateTests.test_model_init

This message can be suppressed by setting PYTORCH_PRINT_REPRO_ON_FAILURE=0</failure></testcase></testsuite></testsuites>